<?xml version="1.0" encoding="utf-8"?>
<!-- This URDF was automatically created by SolidWorks to URDF Exporter! Originally created by Stephen Brawner (brawner@gmail.com) 
     Commit Version: 1.5.1-0-g916b5db  Build Version: 1.5.7152.31018
     For more information, please see http://wiki.ros.org/sw_urdf_exporter -->
<robot name="motar_mini">

<!-- Base_link(Kasa) -->

  <link name="base_link">
    <inertial>
      <origin xyz="0.153101189860761 -0.0850000565633284 0.108422326628583" rpy="0 0 0" />
      <mass value="3" />
      <inertia
        ixx="0.00759545820776308"
        ixy="1.97760419726927E-09"
        ixz="0.000232347400270981"
        iyy="0.0124931975262406"
        iyz="-4.39398457251671E-10"
        izz="0.0148889510280612" />
    </inertial>
    <visual>
      <origin xyz="0 0 0" rpy="0 0 0" />
      <geometry>
        <mesh filename="package://motar_mini/meshes/base_link.STL" />
      </geometry>
      <material name="">
        <color rgba="0.968627450980392 0.258823529411765 0.258823529411765 1" />
      </material>
    </visual>
    <collision>
      <origin xyz="0 0 0" rpy="0 0 0" />
      <geometry>
        <mesh filename="package://motar_mini/meshes/base_link.STL" />
      </geometry>
    </collision>
  </link>

<!-- SWIWEL WHEEL -->

<!-- Swivel Wheel Base-->
  <link name="SWheelbase">
    <inertial>
      <origin xyz="2.7426E-09 -1.1481E-10 -0.0016836" rpy="0 0 0" />
      <mass  value="0.2" />
      <inertia
        ixx="1.4785E-07"
        ixy="-3.9067E-21"
        ixz="6.2429E-15"
        iyy="1.3208E-07"
        iyz="4.1764E-18"
        izz="2.6366E-07" />
    </inertial>
    <visual>
      <origin xyz="0 0 0" rpy="0 0 0" />
      <geometry>
        <mesh filename="package://motar_mini/meshes/SWheelbase.STL" />
      </geometry>
      <material name="">
        <color rgba="0.89804 0.92157 0.92941 1" />
      </material>
    </visual>
    <collision>
      <origin xyz="0 0 0" rpy="0 0 0" />
      <geometry>
        <mesh filename="package://motar_mini/meshes/SWheelbase.STL" />
      </geometry>
    </collision>
  </link>
  <joint  name="SWhBase" type="fixed">
    <origin xyz="0.272999999872566 -0.0849999999212055 0.039802668970508" rpy="0 0 0" />
    <parent link="base_link" />
    <child link="SWheelbase" />
    <axis xyz="0 0 0" />
  </joint>
<!-- Swivel Wheel Dir-->
  <link name="SWhDir">
    <inertial>
      <origin xyz="-0.0088807 0.00045181 -0.0021842" rpy="0 0 0" />
      <mass value="0.5" />
      <inertia
        ixx="2.928E-07"
        ixy="9.276E-09"
        ixz="-9.191E-08"
        iyy="2.9964E-07"
        iyz="1.1937E-08"
        izz="3.2424E-07" />
    </inertial>
    <visual>
      <origin xyz="0 0 0" rpy="0 0 0" />
      <geometry>
        <mesh filename="package://motar_mini/meshes/SWhDir.STL" />
      </geometry>
      <material name="">
        <color rgba="0.89804 0.92157 0.92941 1" />
      </material>
    </visual>
    <collision>
      <origin xyz="0 0 0" rpy="0 0 0" />
      <geometry>
        <mesh filename="package://motar_mini/meshes/SWhDir.STL" />
      </geometry>
    </collision>
  </link>
  <joint name="SWhD" type="continuous">
    <origin xyz="0.00221976872885976 0 -0.0104225951353673" rpy="0 0 0" />
    <parent link="SWheelbase" />
    <child link="SWhDir" />
    <axis xyz="0 0 -1" />
  </joint>
<!-- Swivel Wheel-->
  <link name="SWheel">
    <inertial>
      <origin xyz="1.2147E-06 1.96E-07 8.0438E-07" rpy="0 0 0" />
      <mass value="1" />
      <inertia ixx="4.3731E-07" ixy="-4.6068E-10" ixz="-4.0444E-11"
        iyy="7.3808E-07" iyz="-7.0587E-12" izz="4.3734E-07" />
    </inertial>
    <visual>
      <origin xyz="0 0 0" rpy="0 0 0" />
      <geometry>
        <mesh filename="package://motar_mini/meshes/SWheel.STL" />
      </geometry>
      <material name="">
        <color rgba="0.29412 0.29412 0.29412 1" />
      </material>
    </visual>
    <collision>
      <origin xyz="0 0 0" rpy="0 0 0" />
      <geometry>
        <mesh filename="package://motar_mini/meshes/SWheel.STL" />
      </geometry>
    </collision>
  </link>
  <joint name="SWh" type="continuous">
    <origin  xyz="-0.0177197511672673 -2.65387885129836E-05 -0.0136774048347897" rpy="0 0 0" />
    <parent link="SWhDir" />
    <child  link="SWheel" />
    <axis xyz="0.00149757402447565 -0.999998878635392 0" />
  </joint>

<!-- Left Wheel-->

  <link name="leftWheel">
    <inertial>
      <origin  xyz="-1.7347E-18 -0.0092827 5.5511E-17" rpy="0 0 0" />
      <mass value="1" />
      <inertia
        ixx="0.00016712"
        ixy="-3.0213E-21"
        ixz="1.3911E-17"
        iyy="0.00032266"
        iyz="-9.8863E-21"
        izz="0.00016712" />
    </inertial>
    <visual>
      <origin xyz="0 0 0" rpy="0 0 0" />
      <geometry>
        <mesh filename="package://motar_mini/meshes/leftWheel.STL" />
      </geometry>
      <material name="">
        <color rgba="0.63922 0.4 0.21176 1" />
      </material>
    </visual>
    <collision>
      <origin xyz="0 0 0" rpy="0 0 0" />
      <geometry>
        <mesh filename="package://motar_mini/meshes/leftWheel.STL" />
      </geometry>
    </collision>
  </link>
  <joint name="LWheel" type="continuous">
    <origin xyz="0.0858451267270673 0.0181457276792751 0.060002668970508" rpy="0 0 0" />
    <parent link="base_link" />
    <child link="leftWheel" />
    <axis xyz="0 1 0" />
  </joint>

<!-- Right Wheel-->

  <link name="rightWheel">
    <inertial>
      <origin xyz="1.0408E-17 0.0090244 0" rpy="0 0 0" />
      <mass value="1" />
      <inertia
        ixx="0.00016712"
        ixy="2.3086E-21"
        ixz="1.4729E-18"
        iyy="0.00032266"
        iyz="-1.8672E-21"
        izz="0.00016712" />
    </inertial>
    <visual>
      <origin xyz="0 0 0" rpy="0 0 0" />
      <geometry>
        <mesh filename="package://motar_mini/meshes/rightWheel.STL" />
      </geometry>
      <material name="">
        <color rgba="0.79216 0.81961 0.93333 1" />
      </material>
    </visual>
    <collision>
      <origin xyz="0 0 0" rpy="0 0 0" />
      <geometry>
        <mesh filename="package://motar_mini/meshes/rightWheel.STL" />
      </geometry>
    </collision>
  </link>
  <joint name="RWheel" type="continuous">
    <origin xyz="0.0858451267270673 -0.187145727679275 0.060002668970508" rpy="0 0 0" />
    <parent link="base_link" />
    <child link="rightWheel" />
    <axis xyz="0 1 0" />
  </joint>

<!-- Dolap-->

  <link name="Dolap">
    <inertial>
      <origin xyz="-0.0038285 0.0010421 0.23126" rpy="0 0 0" />
      <mass value="5" />
      <inertia
        ixx="0.04108"
        ixy="8.4741E-06"
        ixz="-0.00024734"
        iyy="0.051851"
        iyz="-0.0004415"
        izz="0.037286" />
    </inertial>
    <visual>
      <origin xyz="0 0 0" rpy="0 0 0" />
      <geometry>
        <mesh filename="package://motar_mini/meshes/Dolap.STL" />
      </geometry>
      <material name="">
        <color rgba="0.29804 0.29804 0.29804 1" />
      </material>
    </visual>
    <collision>
      <origin xyz="0 0 0" rpy="0 0 0" />
      <geometry>
        <mesh filename="package://motar_mini/meshes/Dolap.STL" />
      </geometry>
    </collision>
  </link>
  <joint name="Dolap" type="fixed">
    <origin xyz="0.152 -0.085 0.166002668970508" rpy="0 0 0" />
    <parent link="base_link" />
    <child link="Dolap" />
    <axis xyz="0 0 0" />
  </joint>
  
<!-- Sonar Left-->

  <link name="SL">
    <inertial>
      <origin xyz="-0.11671 0.11418 -4.9387E-05" rpy="0 0 0" />
      <mass value="0.2" />
      <inertia
        ixx="1.74E-07"
        ixy="-3.9565E-10"
        ixz="-1.6556E-09"
        iyy="9.3681E-07"
        iyz="2.8113E-09"
        izz="8.8636E-07" />
    </inertial>
    <visual>
      <origin xyz="0 0 0" rpy="0 0 0" />
      <geometry>
        <mesh filename="package://motar_mini/meshes/SL.STL" />
      </geometry>
      <material name="">
        <color rgba="0.79216 0.81961 0.93333 1" />
      </material>
    </visual>
    <collision>
      <origin xyz="0 0 0" rpy="0 0 0" />
      <geometry>
        <mesh filename="package://motar_mini/meshes/SL.STL" />
      </geometry>
    </collision>
  </link>
  <joint name="SL" type="fixed">
    <origin xyz="0.276499221592938 -0.167500778407062 0.101002668970508" rpy="0 0 -0.785398163397448" />
    <parent link="base_link" />
    <child link="SL" />
    <axis xyz="0 0 0" />
  </joint>

<!-- Sonar Front-->

  <link name="SF">
    <inertial>
      <origin xyz="-0.0024954 -1.8887E-05 4.9385E-05" rpy="0 0 0" />
      <mass value="0.2" />
      <inertia
        ixx="9.3681E-07"
        ixy="-3.9566E-10"
        ixz="-2.8114E-09"
        iyy="1.74E-07"
        iyz="1.6556E-09"
        izz="8.8636E-07" />
    </inertial>
    <visual>
      <origin xyz="0 0 0" rpy="0 0 0" />
      <geometry>
        <mesh filename="package://motar_mini/meshes/SF.STL" />
      </geometry>
      <material name="">
        <color rgba="0.79216 0.81961 0.93333 1" />
      </material>
    </visual>
    <collision>
      <origin xyz="0 0 0" rpy="0 0 0" />
      <geometry>
        <mesh filename="package://motar_mini/meshes/SF.STL" />
      </geometry>
    </collision>
  </link>
  <joint name="SF" type="fixed">
    <origin xyz="0.299 -0.085 0.101002668970508" rpy="0 0 0" />
    <parent link="base_link" />
    <child link="SF" />
    <axis xyz="0 0 0" />
  </joint>

<!-- Sonar Right-->

  <link name="SR">
    <inertial>
      <origin xyz="-0.11667 -0.11418 4.9387E-05" rpy="0 0 0" />
      <mass value="0.2" />
      <inertia
        ixx="1.74E-07"
        ixy="3.9565E-10"
        ixz="1.6556E-09"
        iyy="9.3681E-07"
        iyz="2.8113E-09"
        izz="8.8636E-07" />
    </inertial>
    <visual>
      <origin xyz="0 0 0" rpy="0 0 0" />
      <geometry>
        <mesh filename="package://motar_mini/meshes/SR.STL" />
      </geometry>
      <material name="">
        <color rgba="0.79216 0.81961 0.93333 1" />
      </material>
    </visual>
    <collision>
      <origin xyz="0 0 0" rpy="0 0 0" />
      <geometry>
        <mesh filename="package://motar_mini/meshes/SR.STL" />
      </geometry>
    </collision>
  </link>
  <joint name="SR" type="fixed">
    <origin xyz="0.2765 -0.0025008 0.101" rpy="0 0 0.7854" />
    <parent link="base_link" />
    <child link="SR" />
    <axis xyz="0 0 0" />
  </joint>

<!-- Ultrasonic Sonar Sensors Gazebo Ref. -->
	<gazebo reference="SL">
		<material>Gazebo/Green</material>
		<sensor type="ray" name="SL">
		  <pose>0 0 0 0 0 0</pose>
		  <update_rate>5</update_rate>
		  <ray>
		    <scan>
		      <horizontal>
		        <samples>5</samples>
		        <resolution>1.0</resolution>
		        <min_angle>-0.3</min_angle>
		        <max_angle>0.3</max_angle>
		      </horizontal>
		      <vertical>
		        <samples>5</samples>
		        <resolution>1</resolution>
		        <min_angle>-0.3</min_angle>
		        <max_angle>0.3</max_angle>
		      </vertical>
		    </scan>
		    <range>
		      <min>0.01</min>
		      <max>0.9</max>
		      <resolution>0.01</resolution>
		    </range>
		  </ray>
		  <plugin filename="libgazebo_ros_range.so" name="gazebo_ros_range">
		    <gaussianNoise>0.005</gaussianNoise>
		    <alwaysOn>true</alwaysOn>
		    <updateRate>5</updateRate>
		    <topicName>SL</topicName>
		    <frameName>SL</frameName>
		    <fov>0.7</fov>
		    <radiation>ultrasound</radiation>
		  </plugin>
		</sensor>
	</gazebo>

	<gazebo reference="SF">
		<material>Gazebo/Green</material>
		<sensor type="ray" name="SF">
		  <pose>0 0 0 0 0 0</pose>
		  <update_rate>5</update_rate>
		  <ray>
		    <scan>
		      <horizontal>
		        <samples>5</samples>
		        <resolution>1.0</resolution>
		        <min_angle>-0.3</min_angle>
		        <max_angle>0.3</max_angle>
		      </horizontal>
		      <vertical>
		        <samples>5</samples>
		        <resolution>1</resolution>
		        <min_angle>-0.3</min_angle>
		        <max_angle>0.3</max_angle>
		      </vertical>
		    </scan>
		    <range>
		      <min>0.01</min>
		      <max>0.9</max>
		      <resolution>0.01</resolution>
		    </range>
		  </ray>
		  <plugin filename="libgazebo_ros_range.so" name="gazebo_ros_range">
		    <gaussianNoise>0.005</gaussianNoise>
		    <alwaysOn>true</alwaysOn>
		    <updateRate>5</updateRate>
		    <topicName>SF</topicName>
		    <frameName>SF</frameName>
		    <fov>0.7</fov>
		    <radiation>ultrasound</radiation>
		  </plugin>
		</sensor>
	</gazebo>

	<gazebo reference="SR">
		<material>Gazebo/Green</material>
		<sensor type="ray" name="SR">
		  <pose>0 0 0 0 0 0</pose>
		  <update_rate>5</update_rate>
		  <ray>
		    <scan>
		      <horizontal>
		        <samples>5</samples>
		        <resolution>1.0</resolution>
		        <min_angle>-0.3</min_angle>
		        <max_angle>0.3</max_angle>
		      </horizontal>
		      <vertical>
		        <samples>5</samples>
		        <resolution>1</resolution>
		        <min_angle>-0.3</min_angle>
		        <max_angle>0.3</max_angle>
		      </vertical>
		    </scan>
		    <range>
		      <min>0.01</min>
		      <max>0.9</max>
		      <resolution>0.01</resolution>
		    </range>
		  </ray>
		  <plugin filename="libgazebo_ros_range.so" name="gazebo_ros_range">
		    <gaussianNoise>0.005</gaussianNoise>
		    <alwaysOn>true</alwaysOn>
		    <updateRate>5</updateRate>
		    <topicName>SR</topicName>
		    <frameName>SR</frameName>
		    <fov>0.7</fov>
		    <radiation>ultrasound</radiation>
		  </plugin>
		</sensor>
	</gazebo>

<!-- Lidar Sensor -->

<link name="hokuyo_link">
    <inertial>
      <origin xyz="9.1926E-05 0.0067665 -0.0073819" rpy="0 0 0" />
      <mass value="0.5" />
      <inertia
        ixx="0.0009607"
        ixy="8.0198E-07"
        ixz="3.0916E-06"
        iyy="0.00061492"
        iyz="0.00015824"
        izz="0.0010982" />
    </inertial>
    <visual>
      <origin xyz="0 0 0" rpy="0 0 0" />
      <geometry>
        <mesh filename="package://motar_mini/meshes/lidar.STL" />
      </geometry>
      <material name="">
        <color rgba="0.79216 0.81961 0.93333 1" />
      </material>
    </visual>
    <collision>
      <origin xyz="0 0 0" rpy="0 0 0" />
      <geometry>
        <mesh filename="package://motar_mini/meshes/lidar.STL" />
      </geometry>
    </collision>
  </link>
  <joint name="hokuyo_joint" type="fixed">
    <origin xyz="0.145705213844625 -0.0898024549047488 0.618652668970508" rpy="0 0 0" />
    <parent link="base_link" />
    <child link="hokuyo_link" />
    <axis xyz="0 0 0" />
  </joint>
<!--
  <link
    name="hokuyo_link">
    <inertial>
      <origin xyz="-0.0074835 0.010668 9.1926E-05" rpy="0 0 0" />
      <mass value="0.5" />
      <inertia
        ixx="0.00061492"
        ixy="0.00015824"
        ixz="8.0198E-07"
        iyy="0.0010982"
        iyz="3.0916E-06"
        izz="0.0009607" />
    </inertial>
    <visual>
      <origin xyz="0 0 0" rpy="0 0 0" />
      <geometry>
        <mesh filename="package://motar_mini/meshes/Lidar.dae" />
      </geometry>
      <material name="">
        <color rgba="0.79216 0.81961 0.93333 1" />
      </material>
    </visual>
    <collision>
      <origin xyz="0 0 0" rpy="0 0 0" />
      <geometry>
        <mesh filename="package://motar_mini/meshes/Lidar.dae" />
      </geometry>
    </collision>
  </link>
  <joint name="hokuyo_joint" type="fixed">
    <origin xyz="0 0.00944754509525184 0.8256" rpy="0 0 0" />
    <parent
      link="base_link" />
    <child link="hokuyo_link" />
    <axis xyz="0 0 0" />
  </joint>
-->
<!-- hokuyo Sensor Plugin-->

 	<gazebo reference="hokuyo_link">
		<sensor type="ray" name="head_hokuyo_sensor">
		<pose>0 0 0 1 0 0</pose>
		<visualize>false</visualize>
		<update_rate>40</update_rate>
		<ray>
		<scan>
			<horizontal>
				<samples>720</samples>
				<resolution>1</resolution>
				<min_angle>-3.1416</min_angle>
				<max_angle>3.1416</max_angle>
			</horizontal>
		</scan>
		<range>
			<min>0.10</min>
			<max>10.0</max>
			<resolution>0.01</resolution>
		</range>
		<noise>
			<type>gaussian</type>
			<mean>0.0</mean>
			<stddev>0.01</stddev>
		</noise>
		</ray>

	<plugin name="gazebo_ros_head_hokuyo_controller" filename="libgazebo_ros_laser.so">
			<topicName>/motar_mini/laser/scan</topicName>
			<frameName>hokuyo_link</frameName>
		   </plugin>
		</sensor>
	</gazebo>

<!-- Diff Drive Control Plugin -->

  <gazebo>
     <plugin name="differential_drive_controller" filename="libgazebo_ros_diff_drive.so">
       <alwaysOn>true</alwaysOn>
       <legacyMode>false</legacyMode>
       <updateRate>40</updateRate>
       <leftJoint>LWheel</leftJoint>
       <rightJoint>RWheel</rightJoint>
       <wheelSeparation>0.42</wheelSeparation>
       <wheelDiameter>0.12</wheelDiameter>
       <torque>20</torque>
       <commandTopic>cmd_vel</commandTopic>
       <odometryTopic>odom</odometryTopic>
       <odometryFrame>odom</odometryFrame>
       <robotBaseFrame>base_link</robotBaseFrame>
       <robotNamespace>/</robotNamespace>
     </plugin>
  </gazebo> 
<!-- Planar Move Plugin ->
  <gazebo>
     <plugin name="base_controller" filename="libgazebo_ros_planar_move.so">
            <commandTopic>cmd_vel</commandTopic>
            <odometryTopic>odom</odometryTopic>
            <odometryFrame>odom</odometryFrame>
            <odometryRate>100</odometryRate>
            <robotBaseFrame>base_link</robotBaseFrame>
     </plugin>
  </gazebo>
-->

<!-- Color Settings For Gazebo-->
<gazebo reference="base_link">
	<material>Gazebo/DarkGrey</material>
  </gazebo>
  <gazebo reference="Dolap">
	<material>Gazebo/DarkGrey</material>
  </gazebo>
  <gazebo reference="hokuyo_link">
	<material>Gazebo/Blue</material>
  </gazebo>
  <gazebo reference="leftWheel">
	<material>Gazebo/Yellow</material>
  </gazebo>
  <gazebo reference="rightWheel">
	<material>Gazebo/Yellow</material>
  </gazebo>
  <gazebo reference="SWheelbase">
	<material>Gazebo/Yellow</material>
  </gazebo>
  <gazebo reference="SWheel">
	<material>Gazebo/Yellow</material>
  </gazebo>
  <gazebo reference="SWhDir">
	<material>Gazebo/Yellow</material>
  </gazebo>
  
</robot>